<?xml version="1.0" ?>
<!--
    Ignition Gazebo differential drive plugin demo

    Try sending commands:

        ign topic -t "/model/raspimouse/cmd_vel" -m ignition.msgs.Twist -p "linear: {x: 0.5}, angular: {z: 0.05}"

        ign topic -t "/model/raspimouse/cmd_vel" -m ignition.msgs.Twist -p "linear: {x: 1.0}, angular: {z: -0.1}"

    Listen to odometry:

        ign topic -e -t /model/raspimouse/odometry

-->
<sdf version="1.6">
    <world name="diff_drive">

        <physics name="1ms" type="ode">
            <max_step_size>0.001</max_step_size>
            <real_time_factor>1.0</real_time_factor>
        </physics>
        <plugin
            filename="libignition-gazebo-physics-system.so"
            name="ignition::gazebo::systems::Physics">
        </plugin>
        <plugin
            filename="libignition-gazebo-user-commands-system.so"
            name="ignition::gazebo::systems::UserCommands">
        </plugin>
        <plugin
            filename="libignition-gazebo-scene-broadcaster-system.so"
            name="ignition::gazebo::systems::SceneBroadcaster">
        </plugin>

        <gui fullscreen="0">

            <!-- 3D scene -->
            <plugin filename="GzScene3D" name="3D View">
                <ignition-gui>
                    <title>3D View</title>
                    <property type="bool" key="showTitleBar">false</property>
                    <property type="string" key="state">docked</property>
                </ignition-gui>

                <engine>ogre2</engine>
                <scene>scene</scene>
                <ambient_light>0.4 0.4 0.4</ambient_light>
                <background_color>0.8 0.8 0.8</background_color>
                <camera_pose>-6 0 6 0 0.5 0</camera_pose>
            </plugin>

            <!-- World control -->
            <plugin filename="WorldControl" name="World control">
                <ignition-gui>
                    <title>World control</title>
                    <property type="bool" key="showTitleBar">false</property>
                    <property type="bool" key="resizable">false</property>
                    <property type="double" key="height">72</property>
                    <property type="double" key="width">121</property>
                    <property type="double" key="z">1</property>

                    <property type="string" key="state">floating</property>
                    <anchors target="3D View">
                        <line own="left" target="left"/>
                        <line own="bottom" target="bottom"/>
                    </anchors>
                </ignition-gui>

                <play_pause>false</play_pause>
                <step>true</step>
                <start_paused>true</start_paused>
                <service>/world/diff_drive/control</service>
                <stats_topic>/world/diff_drive/stats</stats_topic>

            </plugin>

            <!-- World statistics -->
            <plugin filename="WorldStats" name="World stats">
                <ignition-gui>
                    <title>World stats</title>
                    <property type="bool" key="showTitleBar">false</property>
                    <property type="bool" key="resizable">false</property>
                    <property type="double" key="height">110</property>
                    <property type="double" key="width">290</property>
                    <property type="double" key="z">1</property>

                    <property type="string" key="state">floating</property>
                    <anchors target="3D View">
                        <line own="right" target="right"/>
                        <line own="bottom" target="bottom"/>
                    </anchors>
                </ignition-gui>

                <sim_time>true</sim_time>
                <real_time>true</real_time>
                <real_time_factor>true</real_time_factor>
                <iterations>true</iterations>
                <topic>/world/diff_drive/stats</topic>

            </plugin>

        </gui>

        <light type="directional" name="sun">
            <cast_shadows>true</cast_shadows>
            <pose>0 0 10 0 0 0</pose>
            <diffuse>1 1 1 1</diffuse>
            <specular>0.5 0.5 0.5 1</specular>
            <attenuation>
                <range>1000</range>
                <constant>0.9</constant>
                <linear>0.01</linear>
                <quadratic>0.001</quadratic>
            </attenuation>
            <direction>-0.5 0.1 -0.9</direction>
        </light>

        <model name="ground_plane">
            <static>true</static>
            <link name="link">
                <collision name="collision">
                    <geometry>
                        <plane>
                            <normal>0 0 1</normal>
                        </plane>
                    </geometry>
                </collision>
                <visual name="visual">
                    <geometry>
                        <plane>
                            <normal>0 0 1</normal>
                            <size>100 100</size>
                        </plane>
                    </geometry>
                    <material>
                        <ambient>0.8 0.8 0.8 1</ambient>
                        <diffuse>0.8 0.8 0.8 1</diffuse>
                        <specular>0.8 0.8 0.8 1</specular>
                    </material>
                </visual>
            </link>
        </model>

        <!-- Raspberry Pi Mouse -->
        <model name='raspimouse'>
            <pose>0 0 0.1 0 0 0</pose>

            <link name='body'>
                <pose>0 0 0 0 0 0</pose>
                <inertial>
                    <mass>0.7186</mass>
                    <inertia>
                        <ixx>0.001238161833</ixx>
                        <ixy>0.000000904986</ixy>
                        <ixz>0.000100297310</ixz>
                        <iyy>0.001368529369</iyy>
                        <iyz>0.000022118177</iyz>
                        <izz>0.000784319117</izz>
                    </inertia>
                </inertial>
                <visual name='visual'>
                    <geometry>
                        <mesh>
                            <uri>file:///home/ubuntu/catkin_ws/src/ros1_ign_gazebo_raspimouse/models/raspimouse/meshes/dae/body/RasPiMouse_body.dae</uri>
                            <!-- <uri>meshes/dae/body/RasPiMouse_body.dae</uri> -->
                        </mesh>
                    </geometry>
                    <material>
                        <ambient>0.5 0.5 1.0 1</ambient>
                        <diffuse>0.5 0.5 1.0 1</diffuse>
                        <specular>0.0 0.0 1.0 1</specular>
                    </material>
                </visual>
                <collision name='collision'>
                    <geometry>
                        <mesh>
                            <uri>file:///home/ubuntu/catkin_ws/src/ros1_ign_gazebo_raspimouse/models/raspimouse/meshes/dae/body/RasPiMouse_body.dae</uri>
                            <!-- <uri>meshes/dae/body/RasPiMouse_body.dae</uri> -->
                        </mesh>
                    </geometry>
                </collision>
            </link>

            <link name='left_wheel'>
                <!-- 進行方向　軸方向　ヨー軸方向-->
                <pose>0 0.0425 0.02215 -1.57 0 0</pose>
                <inertial>
                    <mass>0.0113</mass>
                    <inertia>
                        <ixx>0.000002208187</ixx>
                        <ixy>0.000000000001</ixy>
                        <ixz>0.000000004787</ixz>
                        <iyy>0.00000218412</iyy>
                        <iyz>0.000000000003</iyz>
                        <izz>0.000004078299</izz>
                    </inertia>
                </inertial>
                <visual name='visual'>
                    <geometry>
                        <mesh>
                            <uri>file:///home/ubuntu/catkin_ws/src/ros1_ign_gazebo_raspimouse/models/raspimouse/meshes/dae/wheel/RasPiMouse_wheel.dae</uri>
                            <!-- <uri>meshes/dae/wheel/RasPiMouse_wheel.dae</uri> -->
                        </mesh>
                    </geometry>
                    <material>
                        <ambient>0.2 0.2 0.2 1</ambient>
                        <diffuse>0.2 0.2 0.2 1</diffuse>
                        <specular>0.2 0.2 0.2 1</specular>
                    </material>
                </visual>
                <collision name='collision'>
                    <geometry>
                        <mesh>
                            <uri>file:///home/ubuntu/catkin_ws/src/ros1_ign_gazebo_raspimouse/models/raspimouse/meshes/dae/wheel/RasPiMouse_wheel.dae</uri>
                            <!-- <uri>meshes/dae/wheel/RasPiMouse_wheel.dae</uri> -->
                        </mesh>
                    </geometry>
                </collision>
            </link>

            <link name='right_wheel'>
                <pose>0 -0.0425 0.02215 1.5707 0 0</pose>
                <inertial>
                    <mass>0.0113</mass>
                    <inertia>
                        <ixx>0.000002208187</ixx>
                        <ixy>0.000000000001</ixy>
                        <ixz>0.000000004787</ixz>
                        <iyy>0.00000218412</iyy>
                        <iyz>0.000000000003</iyz>
                        <izz>0.000004078299</izz>
                    </inertia>
                </inertial>
                <visual name='visual'>
                    <geometry>
                        <mesh>
                            <uri>file:///home/ubuntu/catkin_ws/src/ros1_ign_gazebo_raspimouse/models/raspimouse/meshes/dae/wheel/RasPiMouse_wheel.dae</uri>
                            <!-- <uri>meshes/dae/wheel/RasPiMouse_wheel.dae</uri> -->
                        </mesh>
                    </geometry>
                    <material>
                        <ambient>0.2 0.2 0.2 1</ambient>
                        <diffuse>0.2 0.2 0.2 1</diffuse>
                        <specular>0.2 0.2 0.2 1</specular>
                    </material>
                </visual>
                <collision name='collision'>
                    <geometry>
                        <mesh>
                            <uri>file:///home/ubuntu/catkin_ws/src/ros1_ign_gazebo_raspimouse/models/raspimouse/meshes/dae/wheel/RasPiMouse_wheel.dae</uri>
                            <!-- <uri>meshes/dae/wheel/RasPiMouse_wheel.dae</uri> -->
                        </mesh>
                    </geometry>
                </collision>
            </link>

            <joint name='left_wheel_joint' type='revolute'>
                <parent>body</parent>
                <child>left_wheel</child>
                <axis>
                    <xyz>0 0 1</xyz>
                    <limit>
                        <lower>-1.79769e+308</lower>
                        <upper>1.79769e+308</upper>
                    </limit>
                </axis>
            </joint>

            <joint name='right_wheel_joint' type='revolute'>
                <parent>body</parent>
                <child>right_wheel</child>
                <axis>
                    <xyz>0 0 -1</xyz>
                    <limit>
                        <lower>-1.79769e+308</lower>
                        <upper>1.79769e+308</upper>
                    </limit>
                </axis>
            </joint>


            <plugin
                filename="libignition-gazebo-diff-drive-system.so"
                name="ignition::gazebo::systems::DiffDrive">
                <left_joint>left_wheel_joint</left_joint>
                <right_joint>right_wheel_joint</right_joint>
                <wheel_separation>0.0935</wheel_separation>
                <wheel_radius>0.024</wheel_radius>
            </plugin>

        </model>


    </world>
</sdf>
